    previous_failed_cases = None
    failed_cases_changed = 0
    max_attempts = 3

    while failed_cases_changed < max_attempts:
        pytest_result = test_flow.run_pytest(test_file_path)
        if pytest_result["returncode"] == 0:
            logging.info("All tests passed successfully!")
            break

        failed_cases = test_flow.extract_failed_test_cases(pytest_result)
        if failed_cases == previous_failed_cases:
            failed_cases_changed += 1
            logging.warning(
                f"Try {failed_cases_changed} - No change in failed test cases after correction. Reviewing test feasibility..."
            )
            
        if failed_cases_changed >= max_attempts:
            logging.error("Maximum attempts reached with no resolution.")
            logging.info("Regenerating or analyzing tests due to repeated failures.")
            failed_cases_changed=0
        # Instance of the UnitTestFlow class
        test_flow = UnitTestFlow(
            function_to_test=args.class_or_method,
            function_filename=args.file_name,
            explain_model=explain_model,
            plan_model=plan_model,
            execute_model=execute_model,
            temperature=0.4 + 0.6 * failed_cases_changed / failed_cases_changed_max,
        )
        test_file_path = test_flow.run()
        continue            

        previous_failed_cases = failed_cases
        
        # Assuming we have a method to handle test corrections:
        # This part should be adjusted according to your real correction mechanism
        # For now, re-running the test generation as a placeholder for actual correction logic
        test_file_path = test_flow.run()

    logging.info("Test generation and correction loop completed.")